Workbook
Name budget: 'Budget dashboard'!$L1
Name budget_range: 'Budget dashboard'!$Q1
Name budget_rank: 'Budget dashboard'!$R1
Name cc_budget: Calculations!$K1
Name cc_delta: Calculations!$L1
Name cc_in_focus: Calculations!$G1
Name cc_month_number: Calculations!$F1
Name cc_show_rem_budget: Calculations!$I1
Name cc_show_type: Calculations!$H1
Name cc_tracked: Calculations!$J1
Name cc_type: Calculations!$E1
Name comb_rank: 'Budget dashboard'!$S1
Name comb_rank_norm: 'Budget dashboard'!$U1
Name comb_rank_norm_run_range: 'Budget dashboard'!$V1
Name comb_rank_range: 'Budget dashboard'!$T1
Name comb_rank_unique: 'Budget dashboard'!$W1
Name current_date: TODAY()
Name expenses_header_row: ROW(Expenses[[#Headers],[Expenses]])
Name expenses_max_row: MAX(ROW(Expenses[]))
Name expenses_min_row: MIN(ROW(Expenses[]))
Name expenses_total_row: ROW('Budget Planning'!$C$30)
Name header_row_id: 'Budget dashboard'!$D1
Name income_header_row: ROW(Income[[#Headers],[Income]])
Name income_max_row: MAX(ROW(Income[]))
Name income_min_row: MIN(ROW(Income[]))
Name income_total_row: ROW('Budget Planning'!$C$20)
Name is_cat: 'Budget dashboard'!$F1
Name is_empty: 'Budget dashboard'!$H1
Name is_header: 'Budget dashboard'!$E1
Name is_total: 'Budget dashboard'!$G1
Name item: 'Budget dashboard'!$J1
Name left_money_loan: #REF!
Name loan_amount: #REF!
Name out_budget: 'Budget dashboard'!$AA1
Name out_percentage_completed: 'Budget dashboard'!$AB1
Name out_tracked: 'Budget dashboard'!$Z1
Name row_id: 'Budget dashboard'!$C1
Name savings_header_row: ROW(Savings[[#Headers],[Savings]])
Name savings_max_row: MAX(ROW(Savings[]))
Name savings_min_row: MIN(ROW(Savings[]))
Name savings_rate_calculation_type: Settings!$E$22
Name savings_total_row: ROW('Budget Planning'!$C$43)
Name selected_period: Calculations!$E$20
Name selected_period_display: Calculations!$E$21
Name selected_year: Calculations!$E$19
Name Shift_late_income_status: Settings!$E$16
Name Shift_late_starting_day: Settings!$E$18
Name sort_max_row: 'Budget dashboard'!$N1
Name sort_min_row: 'Budget dashboard'!$M1
Name starting_year: Settings!$E$8
Name tracked: 'Budget dashboard'!$K1
Name tracked_range: 'Budget dashboard'!$O1
Name tracked_rank: 'Budget dashboard'!$P1
Name type: 'Budget dashboard'!$I1

Sheet Settings
B1: Settings
C6: General
D8: Starting Year: | E8: 2025
C12: Budget Tracking & Dashboard
D14: Late Monthly Income
D16: Shift late Income: | E16: Active
D18: Starting on day x in month: | E18: 20
D20: KPI Calculation in Dashboard
D22: Savings Rate as % of Income: | E22: % not allocated to Expenses

Sheet Budget Planning
B1: Budget Planning
E5: =starting_year -> 2025 | S5: =E5+1 -> 2026 | AG5: =S5+1 -> 2027
E6: =IF(E7=0,"sty ✓", "sty") -> sty ✓ | F6: =IF(F7=0,"lut ✓", "lut") -> lut | G6: =IF(G7=0,"mar ✓", "mar") -> mar | H6: =IF(H7=0,"kwi ✓", "kwi") -> kwi | I6: =IF(I7=0,"maj ✓", "maj") -> maj | J6: =IF(J7=0,"cze ✓", "cze") -> cze | K6: =IF(K7=0,"lip ✓", "lip") -> lip | L6: =IF(L7=0,"sie ✓", "sie") -> sie | M6: =IF(M7=0,"wrz ✓", "wrz") -> wrz | N6: =IF(N7=0,"paż ✓", "paż") -> paż | O6: =IF(O7=0,"lis ✓", "lis") -> lis | P6: =IF(P7=0,"gru ✓", "gru") -> gru | Q6: =IF(Q7=0,"Total ✓", "Total") -> Total | S6: =IF(S7=0,"sty ✓", "sty") -> sty ✓ | T6: =IF(T7=0,"lut ✓", "lut") -> lut | U6: =IF(U7=0,"mar ✓", "mar") -> mar | V6: =IF(V7=0,"kwi ✓", "kwi") -> kwi | W6: =IF(W7=0,"maj ✓", "maj") -> maj | X6: =IF(X7=0,"cze ✓", "cze") -> cze | Y6: =IF(Y7=0,"lip ✓", "lip") -> lip | Z6: =IF(Z7=0,"sie ✓", "sie") -> sie | AA6: =IF(AA7=0,"wrz ✓", "wrz") -> wrz | AB6: =IF(AB7=0,"paż ✓", "paż") -> paż | AC6: =IF(AC7=0,"lis ✓", "lis") -> lis | AD6: =IF(AD7=0,"gru ✓", "gru") -> gru | AE6: =IF(AE7=0,"Total ✓", "Total") -> Total | AG6: =IF(AG7=0,"sty ✓", "sty") -> sty ✓ | AH6: =IF(AH7=0,"lut ✓", "lut") -> lut ✓ | AI6: =IF(AI7=0,"mar ✓", "mar") -> mar ✓ | AJ6: =IF(AJ7=0,"kwi ✓", "kwi") -> kwi ✓ | AK6: =IF(AK7=0,"maj ✓", "maj") -> maj ✓ | AL6: =IF(AL7=0,"cze ✓", "cze") -> cze ✓ | AM6: =IF(AM7=0,"lip ✓", "lip") -> lip ✓ | AN6: =IF(AN7=0,"sie ✓", "sie") -> sie ✓ | AO6: =IF(AO7=0,"wrz ✓", "wrz") -> wrz ✓ | AP6: =IF(AP7=0,"paż ✓", "paż") -> paż ✓ | AQ6: =IF(AQ7=0,"lis ✓", "lis") -> lis ✓ | AR6: =IF(AR7=0,"gru ✓", "gru") -> gru ✓ | AS6: =IF(AS7=0,"Total ✓", "Total") -> Total ✓
C7: To be allocated: | E7: =E20-(E30+E43) -> 0 | F7: =F20-(F30+F43) -> 600 | G7: =G20-(G30+G43) -> 350 | H7: =H20-(H30+H43) -> 650 | I7: =I20-(I30+I43) -> 650 | J7: =J20-(J30+J43) -> 2350 | K7: =K20-(K30+K43) -> 1750 | L7: =L20-(L30+L43) -> 1100 | ... Q7: =Q20-(Q30+Q43) -> 11750 | S7: =S20-(S30+S43) -> 0 | T7: =T20-(T30+T43) -> 600 | U7: =U20-(U30+U43) -> 350 | V7: =V20-(V30+V43) -> 650 | W7: =W20-(W30+W43) -> 650 | X7: =X20-(X30+X43) -> 2350 | Y7: =Y20-(Y30+Y43) -> 1750 | Z7: =Z20-(Z30+Z43) -> 1100 | ... AE7: =AE20-(AE30+AE43) -> 11750 | AG7: =AG20-(AG30+AG43) -> 0 | AH7: =AH20-(AH30+AH43) -> 0 | AI7: =AI20-(AI30+AI43) -> 0 | AJ7: =AJ20-(AJ30+AJ43) -> 0 | AK7: =AK20-(AK30+AK43) -> 0 | AL7: =AL20-(AL30+AL43) -> 0 | AM7: =AM20-(AM30+AM43) -> 0 | AN7: =AN20-(AN30+AN43) -> 0 | ... AS7: =AS20-(AS30+AS43) -> 0
C9: Income | E9: =DATE(E$5,1,1) -> 45658 | F9: =DATE(E$5,2,1) -> 45689 | G9: =DATE(E$5,3,1) -> 45717 | H9: =DATE(E$5,4,1) -> 45748 | I9: =DATE(E$5,5,1) -> 45778 | J9: =DATE(E$5,6,1) -> 45809 | K9: =DATE(E$5,7,1) -> 45839 | L9: =DATE(E$5,8,1) -> 45870 | M9: =DATE(E$5,9,1) -> 45901 | N9: =DATE(E$5,10,1) -> 45931 | O9: =DATE(E$5,11,1) -> 45962 | P9: =DATE(E$5,12,1) -> 45992 | Q9: =E5 -> 2025 | S9: =DATE(S$5,1,1) -> 46023 | T9: =DATE(S$5,2,1) -> 46054 | U9: =DATE(S$5,3,1) -> 46082 | V9: =DATE(S$5,4,1) -> 46113 | W9: =DATE(S$5,5,1) -> 46143 | X9: =DATE(S$5,6,1) -> 46174 | Y9: =DATE(S$5,7,1) -> 46204 | Z9: =DATE(S$5,8,1) -> 46235 | AA9: =DATE(S$5,9,1) -> 46266 | AB9: =DATE(S$5,10,1) -> 46296 | AC9: =DATE(S$5,11,1) -> 46327 | AD9: =DATE(S$5,12,1) -> 46357 | AE9: =S5 -> 2026 | AG9: =DATE(AG$5,1,1) -> 46388 | AH9: =DATE(AG$5,2,1) -> 46419 | AI9: =DATE(AG$5,3,1) -> 46447 | AJ9: =DATE(AG$5,4,1) -> 46478 | AK9: =DATE(AG$5,5,1) -> 46508 | AL9: =DATE(AG$5,6,1) -> 46539 | AM9: =DATE(AG$5,7,1) -> 46569 | AN9: =DATE(AG$5,8,1) -> 46600 | AO9: =DATE(AG$5,9,1) -> 46631 | AP9: =DATE(AG$5,10,1) -> 46661 | AQ9: =DATE(AG$5,11,1) -> 46692 | AR9: =DATE(AG$5,12,1) -> 46722 | AS9: =AG5 -> 2027
C10: Empoyment(Net) | E10: 8500 | F10: 8500 | G10: 8800 | H10: 8800 | I10: 8800 | J10: 8800 | K10: 8800 | L10: 9200 | M10: 9200 | N10: 9200 | O10: 8500 | P10: 9000 | Q10: =SUM(E10:P10) -> 106100 | S10: 8500 | T10: 8500 | U10: 8800 | V10: 8800 | W10: 8800 | X10: 8800 | Y10: 8800 | Z10: 9200 | AA10: 9200 | AB10: 9200 | AC10: 8500 | AD10: 9000 | AE10: =SUM(S10:AD10) -> 106100 | AS10: =SUM(AG10:AR10) -> 0
C11: Side Hustle(Net) | E11: 1200 | F11: 1800 | G11: 2100 | H11: 1500 | I11: 2400 | J11: 3100 | K11: 2800 | L11: 2200 | M11: 2900 | N11: 1800 | O11: 2550 | P11: 2400 | Q11: =SUM(E11:P11) -> 26750 | S11: 1200 | T11: 1800 | U11: 2100 | V11: 1500 | W11: 2400 | X11: 3100 | Y11: 2800 | Z11: 2200 | AA11: 2900 | AB11: 1800 | AC11: 2550 | AD11: 2400 | AE11: =SUM(S11:AD11) -> 26750 | AS11: =SUM(AG11:AR11) -> 0
C12: Dividents | E12: 50 | F12: 0 | G12: 450 | H12: 0 | I12: 0 | J12: 500 | K12: 0 | L12: 0 | M12: 350 | N12: 1000 | O12: 0 | P12: 1500 | Q12: =SUM(E12:P12) -> 3850 | S12: 50 | T12: 0 | U12: 450 | V12: 0 | W12: 0 | X12: 500 | Y12: 0 | Z12: 0 | AA12: 350 | AB12: 1000 | AC12: 0 | AD12: 1500 | AE12: =SUM(S12:AD12) -> 3850 | AS12: =SUM(AG12:AR12) -> 0
C13: Other | E13: 150 | F13: 300 | G13: 1000 | H13: 400 | I13: 200 | J13: 150 | K13: 600 | L13: 100 | M13: 250 | N13: 350 | O13: 0 | P13: 500 | Q13: =SUM(E13:P13) -> 4000 | S13: 150 | T13: 300 | U13: 1000 | V13: 400 | W13: 200 | X13: 150 | Y13: 600 | Z13: 100 | AA13: 250 | AB13: 350 | AC13: 0 | AD13: 500 | AE13: =SUM(S13:AD13) -> 4000 | AS13: =SUM(AG13:AR13) -> 0
C14: Enter Income Category… | Q14: =SUM(E14:P14) -> 0 | AE14: =SUM(S14:AD14) -> 0 | AS14: =SUM(AG14:AR14) -> 0
C15: Enter Income Category… | Q15: =SUM(E15:P15) -> 0 | AE15: =SUM(S15:AD15) -> 0 | AS15: =SUM(AG15:AR15) -> 0
C16: Enter Income Category… | Q16: =SUM(E16:P16) -> 0 | AE16: =SUM(S16:AD16) -> 0 | AS16: =SUM(AG16:AR16) -> 0
C17: Enter Income Category… | Q17: =SUM(E17:P17) -> 0 | AE17: =SUM(S17:AD17) -> 0 | AS17: =SUM(AG17:AR17) -> 0
C18: Enter Income Category… | Q18: =SUM(E18:P18) -> 0 | AE18: =SUM(S18:AD18) -> 0 | AS18: =SUM(AG18:AR18) -> 0
C19: Enter Income Category… | Q19: =SUM(E19:P19) -> 0 | AE19: =SUM(S19:AD19) -> 0 | AS19: =SUM(AG19:AR19) -> 0
C20: Total | E20: {=SUM(INDIRECT(ADDRESS(income_min_row,COLUMN()) & ":" & ADDRESS(income_max_row,COLUMN())))} -> 9900 | F20: {=SUM(INDIRECT(ADDRESS(income_min_row,COLUMN()) & ":" & ADDRESS(income_max_row,COLUMN())))} -> 10600 | G20: {=SUM(INDIRECT(ADDRESS(income_min_row,COLUMN()) & ":" & ADDRESS(income_max_row,COLUMN())))} -> 12350 | H20: {=SUM(INDIRECT(ADDRESS(income_min_row,COLUMN()) & ":" & ADDRESS(income_max_row,COLUMN())))} -> 10700 | I20: {=SUM(INDIRECT(ADDRESS(income_min_row,COLUMN()) & ":" & ADDRESS(income_max_row,COLUMN())))} -> 11400 | J20: {=SUM(INDIRECT(ADDRESS(income_min_row,COLUMN()) & ":" & ADDRESS(income_max_row,COLUMN())))} -> 12550 | K20: {=SUM(INDIRECT(ADDRESS(income_min_row,COLUMN()) & ":" & ADDRESS(income_max_row,COLUMN())))} -> 12200 | L20: {=SUM(INDIRECT(ADDRESS(income_min_row,COLUMN()) & ":" & ADDRESS(income_max_row,COLUMN())))} -> 11500 | ... Q20: {=SUM(INDIRECT(ADDRESS(income_min_row,COLUMN()) & ":" & ADDRESS(income_max_row,COLUMN())))} -> 140700 | S20: {=SUM(INDIRECT(ADDRESS(income_min_row,COLUMN()) & ":" & ADDRESS(income_max_row,COLUMN())))} -> 9900 | T20: {=SUM(INDIRECT(ADDRESS(income_min_row,COLUMN()) & ":" & ADDRESS(income_max_row,COLUMN())))} -> 10600 | U20: {=SUM(INDIRECT(ADDRESS(income_min_row,COLUMN()) & ":" & ADDRESS(income_max_row,COLUMN())))} -> 12350 | V20: {=SUM(INDIRECT(ADDRESS(income_min_row,COLUMN()) & ":" & ADDRESS(income_max_row,COLUMN())))} -> 10700 | W20: {=SUM(INDIRECT(ADDRESS(income_min_row,COLUMN()) & ":" & ADDRESS(income_max_row,COLUMN())))} -> 11400 | X20: {=SUM(INDIRECT(ADDRESS(income_min_row,COLUMN()) & ":" & ADDRESS(income_max_row,COLUMN())))} -> 12550 | Y20: {=SUM(INDIRECT(ADDRESS(income_min_row,COLUMN()) & ":" & ADDRESS(income_max_row,COLUMN())))} -> 12200 | Z20: {=SUM(INDIRECT(ADDRESS(income_min_row,COLUMN()) & ":" & ADDRESS(income_max_row,COLUMN())))} -> 11500 | ... AE20: {=SUM(INDIRECT(ADDRESS(income_min_row,COLUMN()) & ":" & ADDRESS(income_max_row,COLUMN())))} -> 140700 | AG20: {=SUM(INDIRECT(ADDRESS(income_min_row,COLUMN()) & ":" & ADDRESS(income_max_row,COLUMN())))} -> 0 | AH20: {=SUM(INDIRECT(ADDRESS(income_min_row,COLUMN()) & ":" & ADDRESS(income_max_row,COLUMN())))} -> 0 | AI20: {=SUM(INDIRECT(ADDRESS(income_min_row,COLUMN()) & ":" & ADDRESS(income_max_row,COLUMN())))} -> 0 | AJ20: {=SUM(INDIRECT(ADDRESS(income_min_row,COLUMN()) & ":" & ADDRESS(income_max_row,COLUMN())))} -> 0 | AK20: {=SUM(INDIRECT(ADDRESS(income_min_row,COLUMN()) & ":" & ADDRESS(income_max_row,COLUMN())))} -> 0 | AL20: {=SUM(INDIRECT(ADDRESS(income_min_row,COLUMN()) & ":" & ADDRESS(income_max_row,COLUMN())))} -> 0 | AM20: {=SUM(INDIRECT(ADDRESS(income_min_row,COLUMN()) & ":" & ADDRESS(income_max_row,COLUMN())))} -> 0 | AN20: {=SUM(INDIRECT(ADDRESS(income_min_row,COLUMN()) & ":" & ADDRESS(income_max_row,COLUMN())))} -> 0 | ... AS20: {=SUM(INDIRECT(ADDRESS(income_min_row,COLUMN()) & ":" & ADDRESS(income_max_row,COLUMN())))} -> 0
C22: Expenses | E22: =DATE(E$5,1,1) -> 45658 | F22: =DATE(E$5,2,1) -> 45689 | G22: =DATE(E$5,3,1) -> 45717 | H22: =DATE(E$5,4,1) -> 45748 | I22: =DATE(E$5,5,1) -> 45778 | J22: =DATE(E$5,6,1) -> 45809 | K22: =DATE(E$5,7,1) -> 45839 | L22: =DATE(E$5,8,1) -> 45870 | M22: =DATE(E$5,9,1) -> 45901 | N22: =DATE(E$5,10,1) -> 45931 | O22: =DATE(E$5,11,1) -> 45962 | P22: =DATE(E$5,12,1) -> 45992 | Q22: =E5 -> 2025 | S22: =DATE(S$5,1,1) -> 46023 | T22: =DATE(S$5,2,1) -> 46054 | U22: =DATE(S$5,3,1) -> 46082 | V22: =DATE(S$5,4,1) -> 46113 | W22: =DATE(S$5,5,1) -> 46143 | X22: =DATE(S$5,6,1) -> 46174 | Y22: =DATE(S$5,7,1) -> 46204 | Z22: =DATE(S$5,8,1) -> 46235 | AA22: =DATE(S$5,9,1) -> 46266 | AB22: =DATE(S$5,10,1) -> 46296 | AC22: =DATE(S$5,11,1) -> 46327 | AD22: =DATE(S$5,12,1) -> 46357 | AE22: =S5 -> 2026 | AG22: =DATE(AG$5,1,1) -> 46388 | AH22: =DATE(AG$5,2,1) -> 46419 | AI22: =DATE(AG$5,3,1) -> 46447 | AJ22: =DATE(AG$5,4,1) -> 46478 | AK22: =DATE(AG$5,5,1) -> 46508 | AL22: =DATE(AG$5,6,1) -> 46539 | AM22: =DATE(AG$5,7,1) -> 46569 | AN22: =DATE(AG$5,8,1) -> 46600 | AO22: =DATE(AG$5,9,1) -> 46631 | AP22: =DATE(AG$5,10,1) -> 46661 | AQ22: =DATE(AG$5,11,1) -> 46692 | AR22: =DATE(AG$5,12,1) -> 46722 | AS22: =AG5 -> 2027
C23: Housing | E23: 4200 | F23: 4200 | G23: 4200 | H23: 4200 | I23: 4200 | J23: 4200 | K23: 4200 | L23: 4200 | M23: 4200 | N23: 4200 | O23: 4200 | P23: 4200 | Q23: =SUM(E23:P23) -> 50400 | S23: 4200 | T23: 4200 | U23: 4200 | V23: 4200 | W23: 4200 | X23: 4200 | Y23: 4200 | Z23: 4200 | AA23: 4200 | AB23: 4200 | AC23: 4200 | AD23: 4200 | AE23: =SUM(S23:AD23) -> 50400 | AS23: =SUM(AG23:AR23) -> 0
C24: Groceries | E24: 1500 | F24: 1450 | G24: 1600 | H24: 1550 | I24: 1500 | J24: 1400 | K24: 1450 | L24: 1500 | M24: 1650 | N24: 1550 | O24: 1600 | P24: 1800 | Q24: =SUM(E24:P24) -> 18550 | S24: 1500 | T24: 1450 | U24: 1600 | V24: 1550 | W24: 1500 | X24: 1400 | Y24: 1450 | Z24: 1500 | AA24: 1650 | AB24: 1550 | AC24: 1600 | AD24: 1800 | AE24: =SUM(S24:AD24) -> 18550 | AS24: =SUM(AG24:AR24) -> 0
C25: Other | E25: 400 | F25: 350 | G25: 600 | H25: 450 | I25: 500 | J25: 300 | K25: 800 | L25: 450 | M25: 300 | N25: 550 | O25: 400 | P25: 900 | Q25: =SUM(E25:P25) -> 6000 | S25: 400 | T25: 350 | U25: 600 | V25: 450 | W25: 500 | X25: 300 | Y25: 800 | Z25: 450 | AA25: 300 | AB25: 550 | AC25: 400 | AD25: 900 | AE25: =SUM(S25:AD25) -> 6000 | AS25: =SUM(AG25:AR25) -> 0
C26: Transport | E26: 150 | F26: 150 | G26: 200 | H26: 150 | I26: 300 | J26: 250 | K26: 150 | L26: 150 | M26: 250 | N26: 150 | O26: 150 | P26: 300 | Q26: =SUM(E26:P26) -> 2350 | S26: 150 | T26: 150 | U26: 200 | V26: 150 | W26: 300 | X26: 250 | Y26: 150 | Z26: 150 | AA26: 250 | AB26: 150 | AC26: 150 | AD26: 300 | AE26: =SUM(S26:AD26) -> 2350 | AS26: =SUM(AG26:AR26) -> 0
C27: Studies | E27: 0 | F27: 0 | G27: 1500 | H27: 0 | I27: 0 | J27: 0 | K27: 0 | L27: 0 | M27: 0 | N27: 1500 | O27: 0 | P27: 500 | Q27: =SUM(E27:P27) -> 3500 | S27: 0 | T27: 0 | U27: 1500 | V27: 0 | W27: 0 | X27: 0 | Y27: 0 | Z27: 0 | AA27: 0 | AB27: 1500 | AC27: 0 | AD27: 500 | AE27: =SUM(S27:AD27) -> 3500 | AS27: =SUM(AG27:AR27) -> 0
C28: Technologies | E28: 150 | F28: 150 | G28: 150 | H28: 150 | I28: 450 | J28: 150 | K28: 150 | L28: 150 | M28: 150 | N28: 150 | O28: 150 | P28: 600 | Q28: =SUM(E28:P28) -> 2550 | S28: 150 | T28: 150 | U28: 150 | V28: 150 | W28: 450 | X28: 150 | Y28: 150 | Z28: 150 | AA28: 150 | AB28: 150 | AC28: 150 | AD28: 600 | AE28: =SUM(S28:AD28) -> 2550 | AS28: =SUM(AG28:AR28) -> 0
C29: Enter Expenses Category… | Q29: =SUM(E29:P29) -> 0 | AE29: =SUM(S29:AD29) -> 0 | AS29: =SUM(AG29:AR29) -> 0
C30: Total | E30: {=SUM(INDIRECT(ADDRESS(expenses_min_row,COLUMN()) & ":" & ADDRESS(expenses_max_row,COLUMN())))} -> 6400 | F30: {=SUM(INDIRECT(ADDRESS(expenses_min_row,COLUMN()) & ":" & ADDRESS(expenses_max_row,COLUMN())))} -> 6300 | G30: {=SUM(INDIRECT(ADDRESS(expenses_min_row,COLUMN()) & ":" & ADDRESS(expenses_max_row,COLUMN())))} -> 8250 | H30: {=SUM(INDIRECT(ADDRESS(expenses_min_row,COLUMN()) & ":" & ADDRESS(expenses_max_row,COLUMN())))} -> 6500 | I30: {=SUM(INDIRECT(ADDRESS(expenses_min_row,COLUMN()) & ":" & ADDRESS(expenses_max_row,COLUMN())))} -> 6950 | J30: {=SUM(INDIRECT(ADDRESS(expenses_min_row,COLUMN()) & ":" & ADDRESS(expenses_max_row,COLUMN())))} -> 6300 | K30: {=SUM(INDIRECT(ADDRESS(expenses_min_row,COLUMN()) & ":" & ADDRESS(expenses_max_row,COLUMN())))} -> 6750 | L30: {=SUM(INDIRECT(ADDRESS(expenses_min_row,COLUMN()) & ":" & ADDRESS(expenses_max_row,COLUMN())))} -> 6450 | ... Q30: {=SUM(INDIRECT(ADDRESS(expenses_min_row,COLUMN()) & ":" & ADDRESS(expenses_max_row,COLUMN())))} -> 83350 | S30: {=SUM(INDIRECT(ADDRESS(expenses_min_row,COLUMN()) & ":" & ADDRESS(expenses_max_row,COLUMN())))} -> 6400 | T30: {=SUM(INDIRECT(ADDRESS(expenses_min_row,COLUMN()) & ":" & ADDRESS(expenses_max_row,COLUMN())))} -> 6300 | U30: {=SUM(INDIRECT(ADDRESS(expenses_min_row,COLUMN()) & ":" & ADDRESS(expenses_max_row,COLUMN())))} -> 8250 | V30: {=SUM(INDIRECT(ADDRESS(expenses_min_row,COLUMN()) & ":" & ADDRESS(expenses_max_row,COLUMN())))} -> 6500 | W30: {=SUM(INDIRECT(ADDRESS(expenses_min_row,COLUMN()) & ":" & ADDRESS(expenses_max_row,COLUMN())))} -> 6950 | X30: {=SUM(INDIRECT(ADDRESS(expenses_min_row,COLUMN()) & ":" & ADDRESS(expenses_max_row,COLUMN())))} -> 6300 | Y30: {=SUM(INDIRECT(ADDRESS(expenses_min_row,COLUMN()) & ":" & ADDRESS(expenses_max_row,COLUMN())))} -> 6750 | Z30: {=SUM(INDIRECT(ADDRESS(expenses_min_row,COLUMN()) & ":" & ADDRESS(expenses_max_row,COLUMN())))} -> 6450 | ... AE30: {=SUM(INDIRECT(ADDRESS(expenses_min_row,COLUMN()) & ":" & ADDRESS(expenses_max_row,COLUMN())))} -> 83350 | AG30: {=SUM(INDIRECT(ADDRESS(expenses_min_row,COLUMN()) & ":" & ADDRESS(expenses_max_row,COLUMN())))} -> 0 | AH30: {=SUM(INDIRECT(ADDRESS(expenses_min_row,COLUMN()) & ":" & ADDRESS(expenses_max_row,COLUMN())))} -> 0 | AI30: {=SUM(INDIRECT(ADDRESS(expenses_min_row,COLUMN()) & ":" & ADDRESS(expenses_max_row,COLUMN())))} -> 0 | AJ30: {=SUM(INDIRECT(ADDRESS(expenses_min_row,COLUMN()) & ":" & ADDRESS(expenses_max_row,COLUMN())))} -> 0 | AK30: {=SUM(INDIRECT(ADDRESS(expenses_min_row,COLUMN()) & ":" & ADDRESS(expenses_max_row,COLUMN())))} -> 0 | AL30: {=SUM(INDIRECT(ADDRESS(expenses_min_row,COLUMN()) & ":" & ADDRESS(expenses_max_row,COLUMN())))} -> 0 | AM30: {=SUM(INDIRECT(ADDRESS(expenses_min_row,COLUMN()) & ":" & ADDRESS(expenses_max_row,COLUMN())))} -> 0 | AN30: {=SUM(INDIRECT(ADDRESS(expenses_min_row,COLUMN()) & ":" & ADDRESS(expenses_max_row,COLUMN())))} -> 0 | ... AS30: {=SUM(INDIRECT(ADDRESS(expenses_min_row,COLUMN()) & ":" & ADDRESS(expenses_max_row,COLUMN())))} -> 0
C32: Savings | E32: =DATE(E$5,1,1) -> 45658 | F32: =DATE(E$5,2,1) -> 45689 | G32: =DATE(E$5,3,1) -> 45717 | H32: =DATE(E$5,4,1) -> 45748 | I32: =DATE(E$5,5,1) -> 45778 | J32: =DATE(E$5,6,1) -> 45809 | K32: =DATE(E$5,7,1) -> 45839 | L32: =DATE(E$5,8,1) -> 45870 | M32: =DATE(E$5,9,1) -> 45901 | N32: =DATE(E$5,10,1) -> 45931 | O32: =DATE(E$5,11,1) -> 45962 | P32: =DATE(E$5,12,1) -> 45992 | Q32: =E5 -> 2025 | S32: =DATE(S$5,1,1) -> 46023 | T32: =DATE(S$5,2,1) -> 46054 | U32: =DATE(S$5,3,1) -> 46082 | V32: =DATE(S$5,4,1) -> 46113 | W32: =DATE(S$5,5,1) -> 46143 | X32: =DATE(S$5,6,1) -> 46174 | Y32: =DATE(S$5,7,1) -> 46204 | Z32: =DATE(S$5,8,1) -> 46235 | AA32: =DATE(S$5,9,1) -> 46266 | AB32: =DATE(S$5,10,1) -> 46296 | AC32: =DATE(S$5,11,1) -> 46327 | AD32: =DATE(S$5,12,1) -> 46357 | AE32: =S5 -> 2026 | AG32: =DATE(AG$5,1,1) -> 46388 | AH32: =DATE(AG$5,2,1) -> 46419 | AI32: =DATE(AG$5,3,1) -> 46447 | AJ32: =DATE(AG$5,4,1) -> 46478 | AK32: =DATE(AG$5,5,1) -> 46508 | AL32: =DATE(AG$5,6,1) -> 46539 | AM32: =DATE(AG$5,7,1) -> 46569 | AN32: =DATE(AG$5,8,1) -> 46600 | AO32: =DATE(AG$5,9,1) -> 46631 | AP32: =DATE(AG$5,10,1) -> 46661 | AQ32: =DATE(AG$5,11,1) -> 46692 | AR32: =DATE(AG$5,12,1) -> 46722 | AS32: =AG5 -> 2027
C33: Emergency Fund | E33: 1200 | F33: 1200 | G33: 1200 | H33: 1200 | I33: 1200 | J33: 1200 | K33: 1200 | L33: 1200 | M33: 1200 | N33: 1200 | O33: 1200 | P33: 1200 | Q33: =SUM(E33:P33) -> 14400 | S33: 1200 | T33: 1200 | U33: 1200 | V33: 1200 | W33: 1200 | X33: 1200 | Y33: 1200 | Z33: 1200 | AA33: 1200 | AB33: 1200 | AC33: 1200 | AD33: 1200 | AE33: =SUM(S33:AD33) -> 14400 | AS33: =SUM(AG33:AR33) -> 0
C34: Retirement Account | E34: 1400 | F34: 1400 | G34: 1400 | H34: 1400 | I34: 1400 | J34: 1400 | K34: 1400 | L34: 1400 | M34: 1400 | N34: 1400 | O34: 1400 | P34: 1400 | Q34: =SUM(E34:P34) -> 16800 | S34: 1400 | T34: 1400 | U34: 1400 | V34: 1400 | W34: 1400 | X34: 1400 | Y34: 1400 | Z34: 1400 | AA34: 1400 | AB34: 1400 | AC34: 1400 | AD34: 1400 | AE34: =SUM(S34:AD34) -> 16800 | AS34: =SUM(AG34:AR34) -> 0
C35: Stock Portfolio | E35: 800 | F35: 900 | G35: 1000 | H35: 700 | I35: 1100 | J35: 1000 | K35: 900 | L35: 1200 | M35: 800 | N35: 1000 | O35: 900 | P35: 1800 | Q35: =SUM(E35:P35) -> 12100 | S35: 800 | T35: 900 | U35: 1000 | V35: 700 | W35: 1100 | X35: 1000 | Y35: 900 | Z35: 1200 | AA35: 800 | AB35: 1000 | AC35: 900 | AD35: 1800 | AE35: =SUM(S35:AD35) -> 12100 | AS35: =SUM(AG35:AR35) -> 0
C36: Other | E36: 100 | F36: 200 | G36: 150 | H36: 250 | I36: 100 | J36: 300 | K36: 200 | L36: 150 | M36: 250 | N36: 200 | O36: 100 | P36: 300 | Q36: =SUM(E36:P36) -> 2300 | S36: 100 | T36: 200 | U36: 150 | V36: 250 | W36: 100 | X36: 300 | Y36: 200 | Z36: 150 | AA36: 250 | AB36: 200 | AC36: 100 | AD36: 300 | AE36: =SUM(S36:AD36) -> 2300 | AS36: =SUM(AG36:AR36) -> 0
C37: Enter Savings Category… | Q37: =SUM(E37:P37) -> 0 | AE37: =SUM(S37:AD37) -> 0 | AS37: =SUM(AG37:AR37) -> 0
C38: Enter Savings Category… | Q38: =SUM(E38:P38) -> 0 | AE38: =SUM(S38:AD38) -> 0 | AS38: =SUM(AG38:AR38) -> 0
C39: Enter Savings Category… | Q39: =SUM(E39:P39) -> 0 | AE39: =SUM(S39:AD39) -> 0 | AS39: =SUM(AG39:AR39) -> 0
C40: Enter Savings Category… | Q40: =SUM(E40:P40) -> 0 | AE40: =SUM(S40:AD40) -> 0 | AS40: =SUM(AG40:AR40) -> 0
C41: Enter Savings Category… | Q41: =SUM(E41:P41) -> 0 | AE41: =SUM(S41:AD41) -> 0 | AS41: =SUM(AG41:AR41) -> 0
C42: Enter Savings Category… | Q42: =SUM(E42:P42) -> 0 | AE42: =SUM(S42:AD42) -> 0 | AS42: =SUM(AG42:AR42) -> 0
C43: Total | E43: {=SUM(INDIRECT(ADDRESS(savings_min_row,COLUMN()) & ":" & ADDRESS(savings_max_row,COLUMN())))} -> 3500 | F43: {=SUM(INDIRECT(ADDRESS(savings_min_row,COLUMN()) & ":" & ADDRESS(savings_max_row,COLUMN())))} -> 3700 | G43: {=SUM(INDIRECT(ADDRESS(savings_min_row,COLUMN()) & ":" & ADDRESS(savings_max_row,COLUMN())))} -> 3750 | H43: {=SUM(INDIRECT(ADDRESS(savings_min_row,COLUMN()) & ":" & ADDRESS(savings_max_row,COLUMN())))} -> 3550 | I43: {=SUM(INDIRECT(ADDRESS(savings_min_row,COLUMN()) & ":" & ADDRESS(savings_max_row,COLUMN())))} -> 3800 | J43: {=SUM(INDIRECT(ADDRESS(savings_min_row,COLUMN()) & ":" & ADDRESS(savings_max_row,COLUMN())))} -> 3900 | K43: {=SUM(INDIRECT(ADDRESS(savings_min_row,COLUMN()) & ":" & ADDRESS(savings_max_row,COLUMN())))} -> 3700 | L43: {=SUM(INDIRECT(ADDRESS(savings_min_row,COLUMN()) & ":" & ADDRESS(savings_max_row,COLUMN())))} -> 3950 | ... Q43: {=SUM(INDIRECT(ADDRESS(savings_min_row,COLUMN()) & ":" & ADDRESS(savings_max_row,COLUMN())))} -> 45600 | S43: {=SUM(INDIRECT(ADDRESS(savings_min_row,COLUMN()) & ":" & ADDRESS(savings_max_row,COLUMN())))} -> 3500 | T43: {=SUM(INDIRECT(ADDRESS(savings_min_row,COLUMN()) & ":" & ADDRESS(savings_max_row,COLUMN())))} -> 3700 | U43: {=SUM(INDIRECT(ADDRESS(savings_min_row,COLUMN()) & ":" & ADDRESS(savings_max_row,COLUMN())))} -> 3750 | V43: {=SUM(INDIRECT(ADDRESS(savings_min_row,COLUMN()) & ":" & ADDRESS(savings_max_row,COLUMN())))} -> 3550 | W43: {=SUM(INDIRECT(ADDRESS(savings_min_row,COLUMN()) & ":" & ADDRESS(savings_max_row,COLUMN())))} -> 3800 | X43: {=SUM(INDIRECT(ADDRESS(savings_min_row,COLUMN()) & ":" & ADDRESS(savings_max_row,COLUMN())))} -> 3900 | Y43: {=SUM(INDIRECT(ADDRESS(savings_min_row,COLUMN()) & ":" & ADDRESS(savings_max_row,COLUMN())))} -> 3700 | Z43: {=SUM(INDIRECT(ADDRESS(savings_min_row,COLUMN()) & ":" & ADDRESS(savings_max_row,COLUMN())))} -> 3950 | ... AE43: {=SUM(INDIRECT(ADDRESS(savings_min_row,COLUMN()) & ":" & ADDRESS(savings_max_row,COLUMN())))} -> 45600 | AG43: {=SUM(INDIRECT(ADDRESS(savings_min_row,COLUMN()) & ":" & ADDRESS(savings_max_row,COLUMN())))} -> 0 | AH43: {=SUM(INDIRECT(ADDRESS(savings_min_row,COLUMN()) & ":" & ADDRESS(savings_max_row,COLUMN())))} -> 0 | AI43: {=SUM(INDIRECT(ADDRESS(savings_min_row,COLUMN()) & ":" & ADDRESS(savings_max_row,COLUMN())))} -> 0 | AJ43: {=SUM(INDIRECT(ADDRESS(savings_min_row,COLUMN()) & ":" & ADDRESS(savings_max_row,COLUMN())))} -> 0 | AK43: {=SUM(INDIRECT(ADDRESS(savings_min_row,COLUMN()) & ":" & ADDRESS(savings_max_row,COLUMN())))} -> 0 | AL43: {=SUM(INDIRECT(ADDRESS(savings_min_row,COLUMN()) & ":" & ADDRESS(savings_max_row,COLUMN())))} -> 0 | AM43: {=SUM(INDIRECT(ADDRESS(savings_min_row,COLUMN()) & ":" & ADDRESS(savings_max_row,COLUMN())))} -> 0 | AN43: {=SUM(INDIRECT(ADDRESS(savings_min_row,COLUMN()) & ":" & ADDRESS(savings_max_row,COLUMN())))} -> 0 | ... AS43: {=SUM(INDIRECT(ADDRESS(savings_min_row,COLUMN()) & ":" & ADDRESS(savings_max_row,COLUMN())))} -> 0

Sheet Budget Tracking
B1: Budget Tracking
C11: Date | D11: Type | E11: Category | F11: Amount | G11: Details | H11: Balance | I11: Effective Date
C12: 45658 | D12: Income | E12: Other | F12: 10 | G12: … | H12: {=SUMPRODUCT(Tracking[Amount], --(Tracking[Date]<=Tracking[[#This Row],[Date]]), (Tracking[Type]<>"Income")*(-1)+(Tracking[Type]="Income"))} -> -823.59 | I12: =IF(AND(Tracking[[#This Row],[Type]]="Income", Shift_late_income_status="Active",DAY(Tracking[[#This Row],[Date]])>=Shift_late_starting_day),DATE(YEAR(Tracking[[#This Row],[Date]]),MONTH(Tracking[[#This Row],[Date]])+1,1),Tracking[[#This Row],[Date]]) -> 45658
C13: 45666 | D13: Income | E13: Empoyment(Net) | F13: 1906.88 | G13: … | H13: {=SUMPRODUCT(Tracking[Amount], --(Tracking[Date]<=Tracking[[#This Row],[Date]]), (Tracking[Type]<>"Income")*(-1)+(Tracking[Type]="Income"))} -> 3776.25 | I13: =IF(AND(Tracking[[#This Row],[Type]]="Income", Shift_late_income_status="Active",DAY(Tracking[[#This Row],[Date]])>=Shift_late_starting_day),DATE(YEAR(Tracking[[#This Row],[Date]]),MONTH(Tracking[[#This Row],[Date]])+1,1),Tracking[[#This Row],[Date]]) -> 45666
C14: 45658 | D14: Expenses | E14: Groceries | F14: 833.59 | G14: ... | H14: {=SUMPRODUCT(Tracking[Amount], --(Tracking[Date]<=Tracking[[#This Row],[Date]]), (Tracking[Type]<>"Income")*(-1)+(Tracking[Type]="Income"))} -> -823.59 | I14: =IF(AND(Tracking[[#This Row],[Type]]="Income", Shift_late_income_status="Active",DAY(Tracking[[#This Row],[Date]])>=Shift_late_starting_day),DATE(YEAR(Tracking[[#This Row],[Date]]),MONTH(Tracking[[#This Row],[Date]])+1,1),Tracking[[#This Row],[Date]]) -> 45658
C15: 45659 | D15: Income | E15: Dividents | F15: 37.94 | G15: ... | H15: {=SUMPRODUCT(Tracking[Amount], --(Tracking[Date]<=Tracking[[#This Row],[Date]]), (Tracking[Type]<>"Income")*(-1)+(Tracking[Type]="Income"))} -> -1171.14 | I15: =IF(AND(Tracking[[#This Row],[Type]]="Income", Shift_late_income_status="Active",DAY(Tracking[[#This Row],[Date]])>=Shift_late_starting_day),DATE(YEAR(Tracking[[#This Row],[Date]]),MONTH(Tracking[[#This Row],[Date]])+1,1),Tracking[[#This Row],[Date]]) -> 45659
C16: 45659 | D16: Income | E16: Other | F16: 57.38 | G16: ... | H16: {=SUMPRODUCT(Tracking[Amount], --(Tracking[Date]<=Tracking[[#This Row],[Date]]), (Tracking[Type]<>"Income")*(-1)+(Tracking[Type]="Income"))} -> -1171.14 | I16: =IF(AND(Tracking[[#This Row],[Type]]="Income", Shift_late_income_status="Active",DAY(Tracking[[#This Row],[Date]])>=Shift_late_starting_day),DATE(YEAR(Tracking[[#This Row],[Date]]),MONTH(Tracking[[#This Row],[Date]])+1,1),Tracking[[#This Row],[Date]]) -> 45659
C17: 45659 | D17: Savings | E17: Retirement Account | F17: 442.87 | G17: ... | H17: {=SUMPRODUCT(Tracking[Amount], --(Tracking[Date]<=Tracking[[#This Row],[Date]]), (Tracking[Type]<>"Income")*(-1)+(Tracking[Type]="Income"))} -> -1171.14 | I17: =IF(AND(Tracking[[#This Row],[Type]]="Income", Shift_late_income_status="Active",DAY(Tracking[[#This Row],[Date]])>=Shift_late_starting_day),DATE(YEAR(Tracking[[#This Row],[Date]]),MONTH(Tracking[[#This Row],[Date]])+1,1),Tracking[[#This Row],[Date]]) -> 45659
C18: 45660 | D18: Expenses | E18: Transport | F18: 212.72 | G18: ... | H18: {=SUMPRODUCT(Tracking[Amount], --(Tracking[Date]<=Tracking[[#This Row],[Date]]), (Tracking[Type]<>"Income")*(-1)+(Tracking[Type]="Income"))} -> -1383.86 | I18: =IF(AND(Tracking[[#This Row],[Type]]="Income", Shift_late_income_status="Active",DAY(Tracking[[#This Row],[Date]])>=Shift_late_starting_day),DATE(YEAR(Tracking[[#This Row],[Date]]),MONTH(Tracking[[#This Row],[Date]])+1,1),Tracking[[#This Row],[Date]]) -> 45660
C19: 45662 | D19: Expenses | E19: Other | F19: 93.89 | G19: ... | H19: {=SUMPRODUCT(Tracking[Amount], --(Tracking[Date]<=Tracking[[#This Row],[Date]]), (Tracking[Type]<>"Income")*(-1)+(Tracking[Type]="Income"))} -> -5724.24 | I19: =IF(AND(Tracking[[#This Row],[Type]]="Income", Shift_late_income_status="Active",DAY(Tracking[[#This Row],[Date]])>=Shift_late_starting_day),DATE(YEAR(Tracking[[#This Row],[Date]]),MONTH(Tracking[[#This Row],[Date]])+1,1),Tracking[[#This Row],[Date]]) -> 45662
C20: 45662 | D20: Expenses | E20: Other | F20: 46.49 | G20: ... | H20: {=SUMPRODUCT(Tracking[Amount], --(Tracking[Date]<=Tracking[[#This Row],[Date]]), (Tracking[Type]<>"Income")*(-1)+(Tracking[Type]="Income"))} -> -5724.24 | I20: =IF(AND(Tracking[[#This Row],[Type]]="Income", Shift_late_income_status="Active",DAY(Tracking[[#This Row],[Date]])>=Shift_late_starting_day),DATE(YEAR(Tracking[[#This Row],[Date]]),MONTH(Tracking[[#This Row],[Date]])+1,1),Tracking[[#This Row],[Date]]) -> 45662
C21: 45662 | D21: Expenses | E21: Housing | F21: 4200 | G21: ... | H21: {=SUMPRODUCT(Tracking[Amount], --(Tracking[Date]<=Tracking[[#This Row],[Date]]), (Tracking[Type]<>"Income")*(-1)+(Tracking[Type]="Income"))} -> -5724.24 | I21: =IF(AND(Tracking[[#This Row],[Type]]="Income", Shift_late_income_status="Active",DAY(Tracking[[#This Row],[Date]])>=Shift_late_starting_day),DATE(YEAR(Tracking[[#This Row],[Date]]),MONTH(Tracking[[#This Row],[Date]])+1,1),Tracking[[#This Row],[Date]]) -> 45662
C22: 45663 | D22: Expenses | E22: Groceries | F22: 666.41 | G22: ... | H22: {=SUMPRODUCT(Tracking[Amount], --(Tracking[Date]<=Tracking[[#This Row],[Date]]), (Tracking[Type]<>"Income")*(-1)+(Tracking[Type]="Income"))} -> -6390.65 | I22: =IF(AND(Tracking[[#This Row],[Type]]="Income", Shift_late_income_status="Active",DAY(Tracking[[#This Row],[Date]])>=Shift_late_starting_day),DATE(YEAR(Tracking[[#This Row],[Date]]),MONTH(Tracking[[#This Row],[Date]])+1,1),Tracking[[#This Row],[Date]]) -> 45663
C23: 45664 | D23: Savings | E23: Stock Portfolio | F23: 239.98 | G23: ... | H23: {=SUMPRODUCT(Tracking[Amount], --(Tracking[Date]<=Tracking[[#This Row],[Date]]), (Tracking[Type]<>"Income")*(-1)+(Tracking[Type]="Income"))} -> -6630.63 | I23: =IF(AND(Tracking[[#This Row],[Type]]="Income", Shift_late_income_status="Active",DAY(Tracking[[#This Row],[Date]])>=Shift_late_starting_day),DATE(YEAR(Tracking[[#This Row],[Date]]),MONTH(Tracking[[#This Row],[Date]])+1,1),Tracking[[#This Row],[Date]]) -> 45664
... C357: 46170 | D357: Savings | E357: Other | F357: 250 | G357: ... | H357: {=SUMPRODUCT(Tracking[Amount], --(Tracking[Date]<=Tracking[[#This Row],[Date]]), (Tracking[Type]<>"Income")*(-1)+(Tracking[Type]="Income"))} -> 22766.97 | I357: =IF(AND(Tracking[[#This Row],[Type]]="Income", Shift_late_income_status="Active",DAY(Tracking[[#This Row],[Date]])>=Shift_late_starting_day),DATE(YEAR(Tracking[[#This Row],[Date]]),MONTH(Tracking[[#This Row],[Date]])+1,1),Tracking[[#This Row],[Date]]) -> 46170

Sheet Budget dashboard
AQ5: Year
AN6: Select the year of view: | AQ6: 2026
AQ8: Period
AN9: Select the period of view: | AQ9: Total Year
Y11: ="Breakdown - "&IF(selected_period="Total Year",selected_year&" (Total Year)",selected_period_display&" "&selected_year) -> Breakdown - 2026 (Total Year) | AF11: ="Summary - "&IF(selected_period="Total Year",selected_year&" (Total Year)",selected_period_display&" "&selected_year) -> Summary - 2026 (Total Year)
C12: row_id | D12: header_row_id | E12: is_header | F12: is_cat | G12: is_total | H12: is_empty | I12: type | J12: item | K12: tracked | L12: budget | M12: sort_min_row | N12: sort_max_row | O12: tracked_range | P12: tracked_rank | Q12: budget_range | R12: budget_rank | S12: comb_rank | T12: comb_rank_range | U12: comb_rank_norm | V12: comb_rank_norm_run_range | W12: comb_rank_unique | X12: sorted_row_id [Lookup]
C13: {=income_header_row} -> 9 | D13: =IF(is_header,row_id, IF(NOT(is_empty),D12,-1)) -> 9 | E13: {=1*OR(row_id=income_header_row,row_id=expenses_header_row,row_id=savings_header_row)} -> 1 | F13: =1*NOT(OR(is_header,is_total,is_empty)) -> 0 | G13: {=1*OR(row_id=expenses_total_row,row_id=savings_total_row,row_id=income_total_row)} -> 0 | H13: =1*OR(row_id="/1", row_id="/2", row_id=-1) -> 0 | I13: {=IFERROR(INDEX('Budget Planning'!$C:$C, header_row_id), "")} -> Income | J13: {=IFERROR(INDEX('Budget Planning'!$C:$C, row_id), "")} -> Income | K13: {=IF(OR(is_header, is_empty), "", IF(is_total, IF(selected_period="Total Year", SUM(Tracking[Amount] * (Tracking[Type]=type) * (YEAR(Tracking[Effective Date])=selected_year)), SUM(Tracking[Amount] * (Tracking[Type]=type) * (YEAR(Tracking[Effective Date])=selected_year) * (MONTH(Tracking[Effective Date])=selected_period))), IF(selected_period="Total Year", SUM(Tracking[Amount] * (Tracking[Type]=type) * (Tracking[Category]=item) * (YEAR(Tracking[Effective Date])=selected_year)), SUM(Tracking[Amount] * (Tracking[Type]=type) * (Tracking[Category]=item) * (YEAR(Tracking[Effective Date])=selected_year) * (MONTH(Tracking[Effective Date])=selected_period))) ) )} | L13: {=IF(OR(is_empty,is_header), "", INDEX('Budget Planning'!$E:$AS, row_id, MATCH(IF(selected_period="Total Year", selected_year, DATE(selected_year, selected_period, 1)),'Budget Planning'!$E$9:$AS$9,0) ))} | M13: {=IF(is_cat, IF(header_row_id=income_header_row, MATCH(income_min_row,$C:$C,0), IF(header_row_id=expenses_header_row, MATCH(expenses_min_row,$C:$C,0), IF(header_row_id=savings_header_row, MATCH(savings_min_row,$C:$C,0), ""))), "")} | N13: {=IF(is_cat, IF(header_row_id=income_header_row, MATCH(income_max_row,$C:$C,0), IF(header_row_id=expenses_header_row, MATCH(expenses_max_row,$C:$C,0), IF(header_row_id=savings_header_row, MATCH(savings_max_row,$C:$C,0), ""))), "")} | O13: =IF(is_cat, ADDRESS(sort_min_row, COLUMN(tracked)) & ":" & ADDRESS(sort_max_row,COLUMN(tracked)), "") | P13: =IF(is_cat, RANK(tracked, INDIRECT(tracked_range), 0),"") | Q13: =IF(is_cat, ADDRESS(sort_min_row, COLUMN(budget)) & ":" & ADDRESS(sort_max_row,COLUMN(budget)), "") | R13: =IF(is_cat, RANK(budget, INDIRECT(budget_range), 0),"") | S13: =IF(is_cat, _xlfn.NUMBERVALUE(tracked_rank & budget_rank), "") | T13: =IF(is_cat, ADDRESS(sort_min_row, COLUMN(comb_rank)) & ":" & ADDRESS(sort_max_row,COLUMN(comb_rank)), "") | U13: =IF(is_cat, RANK(comb_rank, INDIRECT(comb_rank_range),1), "") | V13: =IF(is_cat, ADDRESS(sort_min_row, COLUMN(comb_rank_norm)) & ":" & ADDRESS(ROW(),COLUMN(comb_rank_norm)), "") | W13: =IF(is_cat,comb_rank_norm + COUNTIF(INDIRECT(comb_rank_norm_run_range),comb_rank_norm)-1, "") | X13: =IF(is_cat, header_row_id + comb_rank_unique, row_id) -> 9 | Y13: =IF(is_empty, "", INDEX($J:$J,MATCH(row_id, $X:$X, 0))) -> Income | Z13: =IF(is_empty, "", IF(is_header, "Tracked", INDEX($K:$K, MATCH(row_id, $X:$X,0)))) -> Tracked | AA13: =IF(is_empty, "", IF(is_header, "Budget", INDEX($L:$L, MATCH(row_id, $X:$X,0)))) -> Budget | AB13: =IF(is_empty, "", IF(is_header, "% Compl.", IFERROR(out_tracked / out_budget, "-"))) -> % Compl. | AC13: =IF(is_empty, "", IF(is_header, "Remaining", IF(out_budget - out_tracked > 0, out_budget - out_tracked, 0))) -> Remaining | AD13: =IF(is_empty, "", IF(is_header, "Excess", IF(out_budget - out_tracked < 0, out_tracked - out_budget, 0))) -> Excess
C14: {=IF(C13=-1,-1, IF(C13<income_max_row,C13+1, IF(C13=income_max_row,income_total_row, IF(C13=income_total_row,"/1", IF(C13="/1",expenses_header_row, IF(C13<expenses_max_row,C13+1, IF(C13=expenses_max_row,expenses_total_row, IF(C13=expenses_total_row,"/2", IF(C13="/2",savings_header_row, IF(C13<savings_max_row,C13+1, IF(C13=savings_max_row,savings_total_row,-1)))))))))))} -> 10 | D14: =IF(is_header,row_id, IF(NOT(is_empty),D13,-1)) -> 9 | E14: {=1*OR(row_id=income_header_row,row_id=expenses_header_row,row_id=savings_header_row)} -> 0 | F14: =1*NOT(OR(is_header,is_total,is_empty)) -> 1 | G14: {=1*OR(row_id=expenses_total_row,row_id=savings_total_row,row_id=income_total_row)} -> 0 | H14: =1*OR(row_id="/1", row_id="/2", row_id=-1) -> 0 | I14: {=IFERROR(INDEX('Budget Planning'!$C:$C, header_row_id), "")} -> Income | J14: {=IFERROR(INDEX('Budget Planning'!$C:$C, row_id), "")} -> Empoyment(Net) | K14: {=IF(OR(is_header, is_empty), "", IF(is_total, IF(selected_period="Total Year", SUM(Tracking[Amount] * (Tracking[Type]=type) * (YEAR(Tracking[Effective Date])=selected_year)), SUM(Tracking[Amount] * (Tracking[Type]=type) * (YEAR(Tracking[Effective Date])=selected_year) * (MONTH(Tracking[Effective Date])=selected_period))), IF(selected_period="Total Year", SUM(Tracking[Amount] * (Tracking[Type]=type) * (Tracking[Category]=item) * (YEAR(Tracking[Effective Date])=selected_year)), SUM(Tracking[Amount] * (Tracking[Type]=type) * (Tracking[Category]=item) * (YEAR(Tracking[Effective Date])=selected_year) * (MONTH(Tracking[Effective Date])=selected_period))) ) )} -> 47100 | L14: {=IF(OR(is_empty,is_header), "", INDEX('Budget Planning'!$E:$AS, row_id, MATCH(IF(selected_period="Total Year", selected_year, DATE(selected_year, selected_period, 1)),'Budget Planning'!$E$9:$AS$9,0) ))} -> 106100 | M14: {=IF(is_cat, IF(header_row_id=income_header_row, MATCH(income_min_row,$C:$C,0), IF(header_row_id=expenses_header_row, MATCH(expenses_min_row,$C:$C,0), IF(header_row_id=savings_header_row, MATCH(savings_min_row,$C:$C,0), ""))), "")} -> 14 | N14: {=IF(is_cat, IF(header_row_id=income_header_row, MATCH(income_max_row,$C:$C,0), IF(header_row_id=expenses_header_row, MATCH(expenses_max_row,$C:$C,0), IF(header_row_id=savings_header_row, MATCH(savings_max_row,$C:$C,0), ""))), "")} -> 17 | O14: =IF(is_cat, ADDRESS(sort_min_row, COLUMN(tracked)) & ":" & ADDRESS(sort_max_row,COLUMN(tracked)), "") -> $K$14:$K$17 | P14: =IF(is_cat, RANK(tracked, INDIRECT(tracked_range), 0),"") -> 1 | Q14: =IF(is_cat, ADDRESS(sort_min_row, COLUMN(budget)) & ":" & ADDRESS(sort_max_row,COLUMN(budget)), "") -> $L$14:$L$17 | R14: =IF(is_cat, RANK(budget, INDIRECT(budget_range), 0),"") -> 1 | S14: =IF(is_cat, _xlfn.NUMBERVALUE(tracked_rank & budget_rank), "") -> 11 | T14: =IF(is_cat, ADDRESS(sort_min_row, COLUMN(comb_rank)) & ":" & ADDRESS(sort_max_row,COLUMN(comb_rank)), "") -> $S$14:$S$17 | U14: =IF(is_cat, RANK(comb_rank, INDIRECT(comb_rank_range),1), "") -> 1 | V14: =IF(is_cat, ADDRESS(sort_min_row, COLUMN(comb_rank_norm)) & ":" & ADDRESS(ROW(),COLUMN(comb_rank_norm)), "") -> $U$14:$U$14 | W14: =IF(is_cat,comb_rank_norm + COUNTIF(INDIRECT(comb_rank_norm_run_range),comb_rank_norm)-1, "") -> 1 | X14: =IF(is_cat, header_row_id + comb_rank_unique, row_id) -> 10 | Y14: =IF(is_empty, "", INDEX($J:$J,MATCH(row_id, $X:$X, 0))) -> Empoyment(Net) | Z14: =IF(is_empty, "", IF(is_header, "Tracked", INDEX($K:$K, MATCH(row_id, $X:$X,0)))) -> 47100 | AA14: =IF(is_empty, "", IF(is_header, "Budget", INDEX($L:$L, MATCH(row_id, $X:$X,0)))) -> 106100 | AB14: =IF(is_empty, "", IF(is_header, "% Compl.", IFERROR(out_tracked / out_budget, "-"))) -> 0.44392083 | AC14: =IF(is_empty, "", IF(is_header, "Remaining", IF(out_budget - out_tracked > 0, out_budget - out_tracked, 0))) -> 59000 | AD14: =IF(is_empty, "", IF(is_header, "Excess", IF(out_budget - out_tracked < 0, out_tracked - out_budget, 0))) -> 0
C15: {=IF(C14=-1,-1, IF(C14<income_max_row,C14+1, IF(C14=income_max_row,income_total_row, IF(C14=income_total_row,"/1", IF(C14="/1",expenses_header_row, IF(C14<expenses_max_row,C14+1, IF(C14=expenses_max_row,expenses_total_row, IF(C14=expenses_total_row,"/2", IF(C14="/2",savings_header_row, IF(C14<savings_max_row,C14+1, IF(C14=savings_max_row,savings_total_row,-1)))))))))))} -> 11 | D15: =IF(is_header,row_id, IF(NOT(is_empty),D14,-1)) -> 9 | E15: {=1*OR(row_id=income_header_row,row_id=expenses_header_row,row_id=savings_header_row)} -> 0 | F15: =1*NOT(OR(is_header,is_total,is_empty)) -> 1 | G15: {=1*OR(row_id=expenses_total_row,row_id=savings_total_row,row_id=income_total_row)} -> 0 | H15: =1*OR(row_id="/1", row_id="/2", row_id=-1) -> 0 | I15: {=IFERROR(INDEX('Budget Planning'!$C:$C, header_row_id), "")} -> Income | J15: {=IFERROR(INDEX('Budget Planning'!$C:$C, row_id), "")} -> Side Hustle(Net) | K15: {=IF(OR(is_header, is_empty), "", IF(is_total, IF(selected_period="Total Year", SUM(Tracking[Amount] * (Tracking[Type]=type) * (YEAR(Tracking[Effective Date])=selected_year)), SUM(Tracking[Amount] * (Tracking[Type]=type) * (YEAR(Tracking[Effective Date])=selected_year) * (MONTH(Tracking[Effective Date])=selected_period))), IF(selected_period="Total Year", SUM(Tracking[Amount] * (Tracking[Type]=type) * (Tracking[Category]=item) * (YEAR(Tracking[Effective Date])=selected_year)), SUM(Tracking[Amount] * (Tracking[Type]=type) * (Tracking[Category]=item) * (YEAR(Tracking[Effective Date])=selected_year) * (MONTH(Tracking[Effective Date])=selected_period))) ) )} -> 10931.15 | L15: {=IF(OR(is_empty,is_header), "", INDEX('Budget Planning'!$E:$AS, row_id, MATCH(IF(selected_period="Total Year", selected_year, DATE(selected_year, selected_period, 1)),'Budget Planning'!$E$9:$AS$9,0) ))} -> 26750 | M15: {=IF(is_cat, IF(header_row_id=income_header_row, MATCH(income_min_row,$C:$C,0), IF(header_row_id=expenses_header_row, MATCH(expenses_min_row,$C:$C,0), IF(header_row_id=savings_header_row, MATCH(savings_min_row,$C:$C,0), ""))), "")} -> 14 | N15: {=IF(is_cat, IF(header_row_id=income_header_row, MATCH(income_max_row,$C:$C,0), IF(header_row_id=expenses_header_row, MATCH(expenses_max_row,$C:$C,0), IF(header_row_id=savings_header_row, MATCH(savings_max_row,$C:$C,0), ""))), "")} -> 17 | O15: =IF(is_cat, ADDRESS(sort_min_row, COLUMN(tracked)) & ":" & ADDRESS(sort_max_row,COLUMN(tracked)), "") -> $K$14:$K$17 | P15: =IF(is_cat, RANK(tracked, INDIRECT(tracked_range), 0),"") -> 2 | Q15: =IF(is_cat, ADDRESS(sort_min_row, COLUMN(budget)) & ":" & ADDRESS(sort_max_row,COLUMN(budget)), "") -> $L$14:$L$17 | R15: =IF(is_cat, RANK(budget, INDIRECT(budget_range), 0),"") -> 2 | S15: =IF(is_cat, _xlfn.NUMBERVALUE(tracked_rank & budget_rank), "") -> 22 | T15: =IF(is_cat, ADDRESS(sort_min_row, COLUMN(comb_rank)) & ":" & ADDRESS(sort_max_row,COLUMN(comb_rank)), "") -> $S$14:$S$17 | U15: =IF(is_cat, RANK(comb_rank, INDIRECT(comb_rank_range),1), "") -> 2 | V15: =IF(is_cat, ADDRESS(sort_min_row, COLUMN(comb_rank_norm)) & ":" & ADDRESS(ROW(),COLUMN(comb_rank_norm)), "") -> $U$14:$U$15 | W15: =IF(is_cat,comb_rank_norm + COUNTIF(INDIRECT(comb_rank_norm_run_range),comb_rank_norm)-1, "") -> 2 | X15: =IF(is_cat, header_row_id + comb_rank_unique, row_id) -> 11 | Y15: =IF(is_empty, "", INDEX($J:$J,MATCH(row_id, $X:$X, 0))) -> Side Hustle(Net) | Z15: =IF(is_empty, "", IF(is_header, "Tracked", INDEX($K:$K, MATCH(row_id, $X:$X,0)))) -> 10931.15 | AA15: =IF(is_empty, "", IF(is_header, "Budget", INDEX($L:$L, MATCH(row_id, $X:$X,0)))) -> 26750 | AB15: =IF(is_empty, "", IF(is_header, "% Compl.", IFERROR(out_tracked / out_budget, "-"))) -> 0.40864112 | AC15: =IF(is_empty, "", IF(is_header, "Remaining", IF(out_budget - out_tracked > 0, out_budget - out_tracked, 0))) -> 15818.85 | AD15: =IF(is_empty, "", IF(is_header, "Excess", IF(out_budget - out_tracked < 0, out_tracked - out_budget, 0))) -> 0
C16: {=IF(C15=-1,-1, IF(C15<income_max_row,C15+1, IF(C15=income_max_row,income_total_row, IF(C15=income_total_row,"/1", IF(C15="/1",expenses_header_row, IF(C15<expenses_max_row,C15+1, IF(C15=expenses_max_row,expenses_total_row, IF(C15=expenses_total_row,"/2", IF(C15="/2",savings_header_row, IF(C15<savings_max_row,C15+1, IF(C15=savings_max_row,savings_total_row,-1)))))))))))} -> 12 | D16: =IF(is_header,row_id, IF(NOT(is_empty),D15,-1)) -> 9 | E16: {=1*OR(row_id=income_header_row,row_id=expenses_header_row,row_id=savings_header_row)} -> 0 | F16: =1*NOT(OR(is_header,is_total,is_empty)) -> 1 | G16: {=1*OR(row_id=expenses_total_row,row_id=savings_total_row,row_id=income_total_row)} -> 0 | H16: =1*OR(row_id="/1", row_id="/2", row_id=-1) -> 0 | I16: {=IFERROR(INDEX('Budget Planning'!$C:$C, header_row_id), "")} -> Income | J16: {=IFERROR(INDEX('Budget Planning'!$C:$C, row_id), "")} -> Dividents | K16: {=IF(OR(is_header, is_empty), "", IF(is_total, IF(selected_period="Total Year", SUM(Tracking[Amount] * (Tracking[Type]=type) * (YEAR(Tracking[Effective Date])=selected_year)), SUM(Tracking[Amount] * (Tracking[Type]=type) * (YEAR(Tracking[Effective Date])=selected_year) * (MONTH(Tracking[Effective Date])=selected_period))), IF(selected_period="Total Year", SUM(Tracking[Amount] * (Tracking[Type]=type) * (Tracking[Category]=item) * (YEAR(Tracking[Effective Date])=selected_year)), SUM(Tracking[Amount] * (Tracking[Type]=type) * (Tracking[Category]=item) * (YEAR(Tracking[Effective Date])=selected_year) * (MONTH(Tracking[Effective Date])=selected_period))) ) )} -> 2050 | L16: {=IF(OR(is_empty,is_header), "", INDEX('Budget Planning'!$E:$AS, row_id, MATCH(IF(selected_period="Total Year", selected_year, DATE(selected_year, selected_period, 1)),'Budget Planning'!$E$9:$AS$9,0) ))} -> 3850 | M16: {=IF(is_cat, IF(header_row_id=income_header_row, MATCH(income_min_row,$C:$C,0), IF(header_row_id=expenses_header_row, MATCH(expenses_min_row,$C:$C,0), IF(header_row_id=savings_header_row, MATCH(savings_min_row,$C:$C,0), ""))), "")} -> 14 | N16: {=IF(is_cat, IF(header_row_id=income_header_row, MATCH(income_max_row,$C:$C,0), IF(header_row_id=expenses_header_row, MATCH(expenses_max_row,$C:$C,0), IF(header_row_id=savings_header_row, MATCH(savings_max_row,$C:$C,0), ""))), "")} -> 17 | O16: =IF(is_cat, ADDRESS(sort_min_row, COLUMN(tracked)) & ":" & ADDRESS(sort_max_row,COLUMN(tracked)), "") -> $K$14:$K$17 | P16: =IF(is_cat, RANK(tracked, INDIRECT(tracked_range), 0),"") -> 3 | Q16: =IF(is_cat, ADDRESS(sort_min_row, COLUMN(budget)) & ":" & ADDRESS(sort_max_row,COLUMN(budget)), "") -> $L$14:$L$17 | R16: =IF(is_cat, RANK(budget, INDIRECT(budget_range), 0),"") -> 4 | S16: =IF(is_cat, _xlfn.NUMBERVALUE(tracked_rank & budget_rank), "") -> 34 | T16: =IF(is_cat, ADDRESS(sort_min_row, COLUMN(comb_rank)) & ":" & ADDRESS(sort_max_row,COLUMN(comb_rank)), "") -> $S$14:$S$17 | U16: =IF(is_cat, RANK(comb_rank, INDIRECT(comb_rank_range),1), "") -> 3 | V16: =IF(is_cat, ADDRESS(sort_min_row, COLUMN(comb_rank_norm)) & ":" & ADDRESS(ROW(),COLUMN(comb_rank_norm)), "") -> $U$14:$U$16 | W16: =IF(is_cat,comb_rank_norm + COUNTIF(INDIRECT(comb_rank_norm_run_range),comb_rank_norm)-1, "") -> 3 | X16: =IF(is_cat, header_row_id + comb_rank_unique, row_id) -> 12 | Y16: =IF(is_empty, "", INDEX($J:$J,MATCH(row_id, $X:$X, 0))) -> Dividents | Z16: =IF(is_empty, "", IF(is_header, "Tracked", INDEX($K:$K, MATCH(row_id, $X:$X,0)))) -> 2050 | AA16: =IF(is_empty, "", IF(is_header, "Budget", INDEX($L:$L, MATCH(row_id, $X:$X,0)))) -> 3850 | AB16: =IF(is_empty, "", IF(is_header, "% Compl.", IFERROR(out_tracked / out_budget, "-"))) -> 0.53246753 | AC16: =IF(is_empty, "", IF(is_header, "Remaining", IF(out_budget - out_tracked > 0, out_budget - out_tracked, 0))) -> 1800 | AD16: =IF(is_empty, "", IF(is_header, "Excess", IF(out_budget - out_tracked < 0, out_tracked - out_budget, 0))) -> 0 | AI16: =Calculations!E35 -> Empoyment(Net) | AJ16: =Calculations!F35 -> 47100
C17: {=IF(C16=-1,-1, IF(C16<income_max_row,C16+1, IF(C16=income_max_row,income_total_row, IF(C16=income_total_row,"/1", IF(C16="/1",expenses_header_row, IF(C16<expenses_max_row,C16+1, IF(C16=expenses_max_row,expenses_total_row, IF(C16=expenses_total_row,"/2", IF(C16="/2",savings_header_row, IF(C16<savings_max_row,C16+1, IF(C16=savings_max_row,savings_total_row,-1)))))))))))} -> 13 | D17: =IF(is_header,row_id, IF(NOT(is_empty),D16,-1)) -> 9 | E17: {=1*OR(row_id=income_header_row,row_id=expenses_header_row,row_id=savings_header_row)} -> 0 | F17: =1*NOT(OR(is_header,is_total,is_empty)) -> 1 | G17: {=1*OR(row_id=expenses_total_row,row_id=savings_total_row,row_id=income_total_row)} -> 0 | H17: =1*OR(row_id="/1", row_id="/2", row_id=-1) -> 0 | I17: {=IFERROR(INDEX('Budget Planning'!$C:$C, header_row_id), "")} -> Income | J17: {=IFERROR(INDEX('Budget Planning'!$C:$C, row_id), "")} -> Other | K17: {=IF(OR(is_header, is_empty), "", IF(is_total, IF(selected_period="Total Year", SUM(Tracking[Amount] * (Tracking[Type]=type) * (YEAR(Tracking[Effective Date])=selected_year)), SUM(Tracking[Amount] * (Tracking[Type]=type) * (YEAR(Tracking[Effective Date])=selected_year) * (MONTH(Tracking[Effective Date])=selected_period))), IF(selected_period="Total Year", SUM(Tracking[Amount] * (Tracking[Type]=type) * (Tracking[Category]=item) * (YEAR(Tracking[Effective Date])=selected_year)), SUM(Tracking[Amount] * (Tracking[Type]=type) * (Tracking[Category]=item) * (YEAR(Tracking[Effective Date])=selected_year) * (MONTH(Tracking[Effective Date])=selected_period))) ) )} -> 1000 | L17: {=IF(OR(is_empty,is_header), "", INDEX('Budget Planning'!$E:$AS, row_id, MATCH(IF(selected_period="Total Year", selected_year, DATE(selected_year, selected_period, 1)),'Budget Planning'!$E$9:$AS$9,0) ))} -> 4000 | M17: {=IF(is_cat, IF(header_row_id=income_header_row, MATCH(income_min_row,$C:$C,0), IF(header_row_id=expenses_header_row, MATCH(expenses_min_row,$C:$C,0), IF(header_row_id=savings_header_row, MATCH(savings_min_row,$C:$C,0), ""))), "")} -> 14 | N17: {=IF(is_cat, IF(header_row_id=income_header_row, MATCH(income_max_row,$C:$C,0), IF(header_row_id=expenses_header_row, MATCH(expenses_max_row,$C:$C,0), IF(header_row_id=savings_header_row, MATCH(savings_max_row,$C:$C,0), ""))), "")} -> 17 | O17: =IF(is_cat, ADDRESS(sort_min_row, COLUMN(tracked)) & ":" & ADDRESS(sort_max_row,COLUMN(tracked)), "") -> $K$14:$K$17 | P17: =IF(is_cat, RANK(tracked, INDIRECT(tracked_range), 0),"") -> 4 | Q17: =IF(is_cat, ADDRESS(sort_min_row, COLUMN(budget)) & ":" & ADDRESS(sort_max_row,COLUMN(budget)), "") -> $L$14:$L$17 | R17: =IF(is_cat, RANK(budget, INDIRECT(budget_range), 0),"") -> 3 | S17: =IF(is_cat, _xlfn.NUMBERVALUE(tracked_rank & budget_rank), "") -> 43 | T17: =IF(is_cat, ADDRESS(sort_min_row, COLUMN(comb_rank)) & ":" & ADDRESS(sort_max_row,COLUMN(comb_rank)), "") -> $S$14:$S$17 | U17: =IF(is_cat, RANK(comb_rank, INDIRECT(comb_rank_range),1), "") -> 4 | V17: =IF(is_cat, ADDRESS(sort_min_row, COLUMN(comb_rank_norm)) & ":" & ADDRESS(ROW(),COLUMN(comb_rank_norm)), "") -> $U$14:$U$17 | W17: =IF(is_cat,comb_rank_norm + COUNTIF(INDIRECT(comb_rank_norm_run_range),comb_rank_norm)-1, "") -> 4 | X17: =IF(is_cat, header_row_id + comb_rank_unique, row_id) -> 13 | Y17: =IF(is_empty, "", INDEX($J:$J,MATCH(row_id, $X:$X, 0))) -> Other | Z17: =IF(is_empty, "", IF(is_header, "Tracked", INDEX($K:$K, MATCH(row_id, $X:$X,0)))) -> 1000 | AA17: =IF(is_empty, "", IF(is_header, "Budget", INDEX($L:$L, MATCH(row_id, $X:$X,0)))) -> 4000 | AB17: =IF(is_empty, "", IF(is_header, "% Compl.", IFERROR(out_tracked / out_budget, "-"))) -> 0.25 | AC17: =IF(is_empty, "", IF(is_header, "Remaining", IF(out_budget - out_tracked > 0, out_budget - out_tracked, 0))) -> 3000 | AD17: =IF(is_empty, "", IF(is_header, "Excess", IF(out_budget - out_tracked < 0, out_tracked - out_budget, 0))) -> 0 | AI17: =Calculations!E36 -> Side Hustle(Net) | AJ17: =Calculations!F36 -> 10931.15
C18: {=IF(C17=-1,-1, IF(C17<income_max_row,C17+1, IF(C17=income_max_row,income_total_row, IF(C17=income_total_row,"/1", IF(C17="/1",expenses_header_row, IF(C17<expenses_max_row,C17+1, IF(C17=expenses_max_row,expenses_total_row, IF(C17=expenses_total_row,"/2", IF(C17="/2",savings_header_row, IF(C17<savings_max_row,C17+1, IF(C17=savings_max_row,savings_total_row,-1)))))))))))} -> 20 | D18: =IF(is_header,row_id, IF(NOT(is_empty),D17,-1)) -> 9 | E18: {=1*OR(row_id=income_header_row,row_id=expenses_header_row,row_id=savings_header_row)} -> 0 | F18: =1*NOT(OR(is_header,is_total,is_empty)) -> 0 | G18: {=1*OR(row_id=expenses_total_row,row_id=savings_total_row,row_id=income_total_row)} -> 1 | H18: =1*OR(row_id="/1", row_id="/2", row_id=-1) -> 0 | I18: {=IFERROR(INDEX('Budget Planning'!$C:$C, header_row_id), "")} -> Income | J18: {=IFERROR(INDEX('Budget Planning'!$C:$C, row_id), "")} -> Total | K18: {=IF(OR(is_header, is_empty), "", IF(is_total, IF(selected_period="Total Year", SUM(Tracking[Amount] * (Tracking[Type]=type) * (YEAR(Tracking[Effective Date])=selected_year)), SUM(Tracking[Amount] * (Tracking[Type]=type) * (YEAR(Tracking[Effective Date])=selected_year) * (MONTH(Tracking[Effective Date])=selected_period))), IF(selected_period="Total Year", SUM(Tracking[Amount] * (Tracking[Type]=type) * (Tracking[Category]=item) * (YEAR(Tracking[Effective Date])=selected_year)), SUM(Tracking[Amount] * (Tracking[Type]=type) * (Tracking[Category]=item) * (YEAR(Tracking[Effective Date])=selected_year) * (MONTH(Tracking[Effective Date])=selected_period))) ) )} -> 61081.15 | L18: {=IF(OR(is_empty,is_header), "", INDEX('Budget Planning'!$E:$AS, row_id, MATCH(IF(selected_period="Total Year", selected_year, DATE(selected_year, selected_period, 1)),'Budget Planning'!$E$9:$AS$9,0) ))} -> 140700 | M18: {=IF(is_cat, IF(header_row_id=income_header_row, MATCH(income_min_row,$C:$C,0), IF(header_row_id=expenses_header_row, MATCH(expenses_min_row,$C:$C,0), IF(header_row_id=savings_header_row, MATCH(savings_min_row,$C:$C,0), ""))), "")} | N18: {=IF(is_cat, IF(header_row_id=income_header_row, MATCH(income_max_row,$C:$C,0), IF(header_row_id=expenses_header_row, MATCH(expenses_max_row,$C:$C,0), IF(header_row_id=savings_header_row, MATCH(savings_max_row,$C:$C,0), ""))), "")} | O18: =IF(is_cat, ADDRESS(sort_min_row, COLUMN(tracked)) & ":" & ADDRESS(sort_max_row,COLUMN(tracked)), "") | P18: =IF(is_cat, RANK(tracked, INDIRECT(tracked_range), 0),"") | Q18: =IF(is_cat, ADDRESS(sort_min_row, COLUMN(budget)) & ":" & ADDRESS(sort_max_row,COLUMN(budget)), "") | R18: =IF(is_cat, RANK(budget, INDIRECT(budget_range), 0),"") | S18: =IF(is_cat, _xlfn.NUMBERVALUE(tracked_rank & budget_rank), "") | T18: =IF(is_cat, ADDRESS(sort_min_row, COLUMN(comb_rank)) & ":" & ADDRESS(sort_max_row,COLUMN(comb_rank)), "") | U18: =IF(is_cat, RANK(comb_rank, INDIRECT(comb_rank_range),1), "") | V18: =IF(is_cat, ADDRESS(sort_min_row, COLUMN(comb_rank_norm)) & ":" & ADDRESS(ROW(),COLUMN(comb_rank_norm)), "") | W18: =IF(is_cat,comb_rank_norm + COUNTIF(INDIRECT(comb_rank_norm_run_range),comb_rank_norm)-1, "") | X18: =IF(is_cat, header_row_id + comb_rank_unique, row_id) -> 20 | Y18: =IF(is_empty, "", INDEX($J:$J,MATCH(row_id, $X:$X, 0))) -> Total | Z18: =IF(is_empty, "", IF(is_header, "Tracked", INDEX($K:$K, MATCH(row_id, $X:$X,0)))) -> 61081.15 | AA18: =IF(is_empty, "", IF(is_header, "Budget", INDEX($L:$L, MATCH(row_id, $X:$X,0)))) -> 140700 | AB18: =IF(is_empty, "", IF(is_header, "% Compl.", IFERROR(out_tracked / out_budget, "-"))) -> 0.43412331 | AC18: =IF(is_empty, "", IF(is_header, "Remaining", IF(out_budget - out_tracked > 0, out_budget - out_tracked, 0))) -> 79618.85 | AD18: =IF(is_empty, "", IF(is_header, "Excess", IF(out_budget - out_tracked < 0, out_tracked - out_budget, 0))) -> 0 | AI18: =Calculations!E37 -> Dividents | AJ18: =Calculations!F37 -> 2050
C19: {=IF(C18=-1,-1, IF(C18<income_max_row,C18+1, IF(C18=income_max_row,income_total_row, IF(C18=income_total_row,"/1", IF(C18="/1",expenses_header_row, IF(C18<expenses_max_row,C18+1, IF(C18=expenses_max_row,expenses_total_row, IF(C18=expenses_total_row,"/2", IF(C18="/2",savings_header_row, IF(C18<savings_max_row,C18+1, IF(C18=savings_max_row,savings_total_row,-1)))))))))))} -> /1 | D19: =IF(is_header,row_id, IF(NOT(is_empty),D18,-1)) -> -1 | E19: {=1*OR(row_id=income_header_row,row_id=expenses_header_row,row_id=savings_header_row)} -> 0 | F19: =1*NOT(OR(is_header,is_total,is_empty)) -> 0 | G19: {=1*OR(row_id=expenses_total_row,row_id=savings_total_row,row_id=income_total_row)} -> 0 | H19: =1*OR(row_id="/1", row_id="/2", row_id=-1) -> 1 | I19: {=IFERROR(INDEX('Budget Planning'!$C:$C, header_row_id), "")} | J19: {=IFERROR(INDEX('Budget Planning'!$C:$C, row_id), "")} | K19: {=IF(OR(is_header, is_empty), "", IF(is_total, IF(selected_period="Total Year", SUM(Tracking[Amount] * (Tracking[Type]=type) * (YEAR(Tracking[Effective Date])=selected_year)), SUM(Tracking[Amount] * (Tracking[Type]=type) * (YEAR(Tracking[Effective Date])=selected_year) * (MONTH(Tracking[Effective Date])=selected_period))), IF(selected_period="Total Year", SUM(Tracking[Amount] * (Tracking[Type]=type) * (Tracking[Category]=item) * (YEAR(Tracking[Effective Date])=selected_year)), SUM(Tracking[Amount] * (Tracking[Type]=type) * (Tracking[Category]=item) * (YEAR(Tracking[Effective Date])=selected_year) * (MONTH(Tracking[Effective Date])=selected_period))) ) )} | L19: {=IF(OR(is_empty,is_header), "", INDEX('Budget Planning'!$E:$AS, row_id, MATCH(IF(selected_period="Total Year", selected_year, DATE(selected_year, selected_period, 1)),'Budget Planning'!$E$9:$AS$9,0) ))} | M19: {=IF(is_cat, IF(header_row_id=income_header_row, MATCH(income_min_row,$C:$C,0), IF(header_row_id=expenses_header_row, MATCH(expenses_min_row,$C:$C,0), IF(header_row_id=savings_header_row, MATCH(savings_min_row,$C:$C,0), ""))), "")} | N19: {=IF(is_cat, IF(header_row_id=income_header_row, MATCH(income_max_row,$C:$C,0), IF(header_row_id=expenses_header_row, MATCH(expenses_max_row,$C:$C,0), IF(header_row_id=savings_header_row, MATCH(savings_max_row,$C:$C,0), ""))), "")} | O19: =IF(is_cat, ADDRESS(sort_min_row, COLUMN(tracked)) & ":" & ADDRESS(sort_max_row,COLUMN(tracked)), "") | P19: =IF(is_cat, RANK(tracked, INDIRECT(tracked_range), 0),"") | Q19: =IF(is_cat, ADDRESS(sort_min_row, COLUMN(budget)) & ":" & ADDRESS(sort_max_row,COLUMN(budget)), "") | R19: =IF(is_cat, RANK(budget, INDIRECT(budget_range), 0),"") | S19: =IF(is_cat, _xlfn.NUMBERVALUE(tracked_rank & budget_rank), "") | T19: =IF(is_cat, ADDRESS(sort_min_row, COLUMN(comb_rank)) & ":" & ADDRESS(sort_max_row,COLUMN(comb_rank)), "") | U19: =IF(is_cat, RANK(comb_rank, INDIRECT(comb_rank_range),1), "") | V19: =IF(is_cat, ADDRESS(sort_min_row, COLUMN(comb_rank_norm)) & ":" & ADDRESS(ROW(),COLUMN(comb_rank_norm)), "") | W19: =IF(is_cat,comb_rank_norm + COUNTIF(INDIRECT(comb_rank_norm_run_range),comb_rank_norm)-1, "") | X19: =IF(is_cat, header_row_id + comb_rank_unique, row_id) -> /1 | Y19: =IF(is_empty, "", INDEX($J:$J,MATCH(row_id, $X:$X, 0))) | Z19: =IF(is_empty, "", IF(is_header, "Tracked", INDEX($K:$K, MATCH(row_id, $X:$X,0)))) | AA19: =IF(is_empty, "", IF(is_header, "Budget", INDEX($L:$L, MATCH(row_id, $X:$X,0)))) | AB19: =IF(is_empty, "", IF(is_header, "% Compl.", IFERROR(out_tracked / out_budget, "-"))) | AC19: =IF(is_empty, "", IF(is_header, "Remaining", IF(out_budget - out_tracked > 0, out_budget - out_tracked, 0))) | AD19: =IF(is_empty, "", IF(is_header, "Excess", IF(out_budget - out_tracked < 0, out_tracked - out_budget, 0))) | AI19: =Calculations!E38 -> Other | AJ19: =Calculations!F38 -> 1000
